<mujoco>
    <worldbody>
    <light diffuse=".5 .5 .5" pos="0 0 3" dir="0 0 -1"/>
    <geom type="plane" size="5 5 0.1" rgba=".9 0.9 0.9 1"/>
    <body name="main body" pos="0 0 .2">
        <joint type="free"/>
        <geom type="box" size="0.1823618432185498 0.10347852472478945 0.10960618824937188" rgba="0 0 1 1" mass="1"/>
        <site name="marker" pos="0 0 0" size="0.05"/>
        <site name="robot_center" pos="0 0 0" size="0.01"/>
        <body name="left_leg1" pos="-0.38 0.1671804735007774 -0.020131263965421534">
            <joint name="left_leg1_joint" type="hinge" axis="0 1 0" pos="0 0 0"/>
            <geom type="box" size="0.337457078141294 0.06370194877598793 0.028613444513081326" rgba="0 .5 0 1" mass="1"/>
            <body name="left_leg2" pos="-0.2664028669818799 0.18013244401035755 -0.04">
                <joint name="left_leg2_joint" type="hinge" axis="0 1 0" pos="0 0 0"/>
                <geom type="box" size="0.54796313754881 0.11643049523436962 0.05111184958501502" rgba="0 .6 0 1" mass="1"/>
            </body>
        </body>
        <body name="right_leg1" pos="0.5473671382621346 -0.24701094092847187 -0.08904395584949436">
            <joint name="right_leg1_joint" type="hinge" axis="0 1 0" pos="0 0 0"/>
            <geom type="box" size="0.39752449761803 0.14353241620368243 0.07370081633151675" rgba="0 .5 0 1" mass="1"/>
            <body name="right_leg2" pos="0.1150039822423069 -0.258576841961511 -0.010591158288174191">
                <joint name="right_leg2_joint" type="hinge" axis="0 1 0" pos="0 0 0"/>
                <geom type="box" size="0.33237558943717926 0.11504442575782857 0.12773692616278537" rgba="0 .6 0 1" mass="1"/>
            </body>
        </body>
    </body>
    </worldbody>
    <sensor>
        <framepos objtype="site" objname="marker"/>
        <velocimeter name="robot_velocity" site="robot_center"/>
    </sensor>
    <actuator>
        <position joint="left_leg1_joint" kp="10"/>
        <position joint="left_leg2_joint" kp="10"/>
        <position joint="right_leg1_joint" kp="10"/>
        <position joint="right_leg2_joint" kp="10"/>
    </actuator>
</mujoco>