<mujoco>
    <worldbody>
    <light diffuse=".5 .5 .5" pos="0 0 3" dir="0 0 -1"/>
    <geom type="plane" size="5 5 0.1" rgba=".9 0.9 0.9 1"/>
    <body name="main body" pos="0 0 .2">
        <joint type="free"/>
        <geom type="box" size="0.19107865541566094 0.14200497525542408 0.10083887571139179" rgba="0 0 1 1" mass="1"/>
        <site name="marker" pos="0 0 0" size="0.05"/>
        <site name="robot_center" pos="0 0 0" size="0.01"/>
        <body name="left_leg1" pos="0.2383888367934317 0.29200497525542407 0.13138701101293548">
            <joint name="left_leg1_joint" type="hinge" axis="0 1 0" pos="0 0 0"/>
            <geom type="box" size="0.4501140486512499 0.15 0.14495727735542563" rgba="0 .5 0 1" mass="1"/>
            <body name="left_leg2" pos="0.7867289309682755 0.26199158508383913 -0.04">
                <joint name="left_leg2_joint" type="hinge" axis="0 1 0" pos="0 0 0"/>
                <geom type="box" size="0.403180635746322 0.11199158508383913 0.040891617884899825" rgba="0 .6 0 1" mass="1"/>
            </body>
        </body>
        <body name="right_leg1" pos="-0.1186646952330504 -0.2891322900857701 -0.06228813037867301">
            <joint name="right_leg1_joint" type="hinge" axis="0 1 0" pos="0 0 0"/>
            <geom type="box" size="0.3061285946061422 0.14712731483034602 0.07722528834951585" rgba="0 .5 0 1" mass="1"/>
            <body name="right_leg2" pos="0.4380989564532176 -0.2201589447548618 0.04106208663005556">
                <joint name="right_leg2_joint" type="hinge" axis="0 1 0" pos="0 0 0"/>
                <geom type="box" size="0.33317769863069124 0.07303162992451577 0.15" rgba="0 .6 0 1" mass="1"/>
            </body>
        </body>
    </body>
    </worldbody>
    <sensor>
        <framepos objtype="site" objname="marker"/>
        <velocimeter name="robot_velocity" site="robot_center"/>
    </sensor>
    <actuator>
        <position joint="left_leg1_joint" kp="10"/>
        <position joint="left_leg2_joint" kp="10"/>
        <position joint="right_leg1_joint" kp="10"/>
        <position joint="right_leg2_joint" kp="10"/>
    </actuator>
</mujoco>