<mujoco>
    <worldbody>
    <light diffuse=".5 .5 .5" pos="0 0 3" dir="0 0 -1"/>
    <geom type="plane" size="5 5 0.1" rgba=".9 0.9 0.9 1"/>
    <body name="main body" pos="0 0 .2">
        <joint type="free"/>
        <geom type="box" size="0.18910980119456156 0.16897217128838524 0.08190808726862392" rgba="0 0 1 1" mass="1"/>
        <site name="marker" pos="0 0 0" size="0.05"/>
        <site name="robot_center" pos="0 0 0" size="0.01"/>
        <body name="left_leg1" pos="0.14227198150532794 0.30571173572786614 0.10118941715049358">
            <joint name="left_leg1_joint" type="hinge" axis="0 1 0" pos="0 0 0"/>
            <geom type="box" size="0.36467608989702366 0.1367395644394809 0.0384228106111532" rgba="0 .5 0 1" mass="1"/>
            <body name="left_leg2" pos="-0.5089544144036624 0.23894005358700762 -0.011653448229086358">
                <joint name="left_leg2_joint" type="hinge" axis="0 1 0" pos="0 0 0"/>
                <geom type="box" size="0.4617886540145271 0.10220048914752672 0.04266347290869957" rgba="0 .6 0 1" mass="1"/>
            </body>
        </body>
        <body name="right_leg1" pos="0.3322351192608033 -0.21925312169390426 0.11354489608918877">
            <joint name="right_leg1_joint" type="hinge" axis="0 1 0" pos="0 0 0"/>
            <geom type="box" size="0.44824644421400905 0.05028095040551901 0.13030311877252143" rgba="0 .5 0 1" mass="1"/>
            <body name="right_leg2" pos="-0.3886579667756781 -0.16175489423442369 0.030324597554517524">
                <joint name="right_leg2_joint" type="hinge" axis="0 1 0" pos="0 0 0"/>
                <geom type="box" size="0.33247096630569145 0.11147394382890466 0.02670525447610501" rgba="0 .6 0 1" mass="1"/>
            </body>
        </body>
    </body>
    </worldbody>
    <sensor>
        <framepos objtype="site" objname="marker"/>
        <velocimeter name="robot_velocity" site="robot_center"/>
    </sensor>
    <actuator>
        <position joint="left_leg1_joint" kp="10"/>
        <position joint="left_leg2_joint" kp="10"/>
        <position joint="right_leg1_joint" kp="10"/>
        <position joint="right_leg2_joint" kp="10"/>
    </actuator>
</mujoco>