<mujoco>
    <worldbody>
    <light diffuse=".5 .5 .5" pos="0 0 3" dir="0 0 -1"/>
    <geom type="plane" size="5 5 0.1" rgba=".9 0.9 0.9 1"/>
    <body name="main body" pos="0 0 .2">
        <joint type="free"/>
        <geom type="box" size="0.216828890437737 0.14695411359216412 0.08457970743722419" rgba="0 0 1 1" mass="1"/>
        <site name="marker" pos="0 0 0" size="0.05"/>
        <site name="robot_center" pos="0 0 0" size="0.01"/>
        <body name="left_leg1" pos="0.13965906772716205 0.2969541135921641 0.017813597755427124">
            <joint name="left_leg1_joint" type="hinge" axis="0 1 0" pos="0 0 0"/>
            <geom type="box" size="0.4173292627391199 0.15 0.14837840508433306" rgba="0 .5 0 1" mass="2"/>
            <body name="left_leg2" pos="0.4077833490650727 0.16999999999999998 -0.04">
                <joint name="left_leg2_joint" type="hinge" axis="0 1 0" pos="0 0 0"/>
                <geom type="box" size="0.3 0.02 0.0951312403893938" rgba="0 .6 0 1" mass="2"/>
            </body>
        </body>
        <body name="right_leg1" pos="-0.34219621731838484 -0.1714551670050531 0.06817140635313633">
            <joint name="right_leg1_joint" type="hinge" axis="0 1 0" pos="0 0 0"/>
            <geom type="box" size="0.3 0.024501053412888954 0.0865329885623749" rgba="0 .5 0 1" mass="2"/>
            <body name="right_leg2" pos="-0.6 -0.09703629884388483 0.00485217509604664">
                <joint name="right_leg2_joint" type="hinge" axis="0 1 0" pos="0 0 0"/>
                <geom type="box" size="0.4334125767677493 0.07253524543099588 0.08888711324718784" rgba="0 .6 0 1" mass="2"/>
            </body>
        </body>
    </body>
    </worldbody>
    <sensor>
        <framepos objtype="site" objname="marker"/>
        <velocimeter name="robot_velocity" site="robot_center"/>
    </sensor>
    <actuator>
        <position joint="left_leg1_joint" kp="10"/>
        <position joint="left_leg2_joint" kp="10"/>
        <position joint="right_leg1_joint" kp="10"/>
        <position joint="right_leg2_joint" kp="10"/>
    </actuator>
</mujoco>