<mujoco>
    <worldbody>
    <light diffuse=".5 .5 .5" pos="0 0 3" dir="0 0 -1"/>
    <geom type="plane" size="5 5 0.1" rgba=".9 0.9 0.9 1"/>
    <body name="main body" pos="0 0 .2">
        <joint type="free"/>
        <geom type="box" size="0.18047773148719906 0.13080066254240705 0.11916331009378561" rgba="0 0 1 1" mass="1"/>
        <site name="marker" pos="0 0 0" size="0.05"/>
        <site name="robot_center" pos="0 0 0" size="0.01"/>
        <body name="left_leg1" pos="-0.3291747024742631 0.18988389502805877 0.023279240054351114">
            <joint name="left_leg1_joint" type="hinge" axis="0 1 0" pos="0 0 0"/>
            <geom type="box" size="0.36819440166063305 0.05908323248565173 0.12480892963960383" rgba="0 .5 0 1" mass="2"/>
            <body name="left_leg2" pos="0.5485452647270391 0.18098970052843838 -0.04">
                <joint name="left_leg2_joint" type="hinge" axis="0 1 0" pos="0 0 0"/>
                <geom type="box" size="0.3164617686941635 0.12190646804278665 0.04257333171506409" rgba="0 .6 0 1" mass="2"/>
            </body>
        </body>
        <body name="right_leg1" pos="-0.04260883222283396 -0.20884463125000008 -0.059088154744180915">
            <joint name="right_leg1_joint" type="hinge" axis="0 1 0" pos="0 0 0"/>
            <geom type="box" size="0.4708041637031166 0.07804396870759303 0.02" rgba="0 .5 0 1" mass="2"/>
            <body name="right_leg2" pos="-0.5540429468560358 -0.1135801387349309 -0.04">
                <joint name="right_leg2_joint" type="hinge" axis="0 1 0" pos="0 0 0"/>
                <geom type="box" size="0.364205186352617 0.035536170027337874 0.11242486296693348" rgba="0 .6 0 1" mass="2"/>
            </body>
        </body>
    </body>
    </worldbody>
    <sensor>
        <framepos objtype="site" objname="marker"/>
        <velocimeter name="robot_velocity" site="robot_center"/>
    </sensor>
    <actuator>
        <position joint="left_leg1_joint" kp="10"/>
        <position joint="left_leg2_joint" kp="10"/>
        <position joint="right_leg1_joint" kp="10"/>
        <position joint="right_leg2_joint" kp="10"/>
    </actuator>
</mujoco>