<mujoco>
    <worldbody>
    <light diffuse=".5 .5 .5" pos="0 0 3" dir="0 0 -1"/>
    <geom type="plane" size="5 5 0.1" rgba=".9 0.9 0.9 1"/>
    <body name="main body" pos="0 0 .2">
        <joint type="free"/>
        <geom type="box" size="0.21177953004201347 0.13728901900239493 0.1119007409973764" rgba="0 0 1 1" mass="1"/>
        <site name="marker" pos="0 0 0" size="0.05"/>
        <site name="robot_center" pos="0 0 0" size="0.01"/>
        <body name="left_leg1" pos="-0.2866718754066137 0.2724380900326997 0.02898438862421529">
            <joint name="left_leg1_joint" type="hinge" axis="0 1 0" pos="0 0 0"/>
            <geom type="box" size="0.43639650585405665 0.13514907103030474 0.15" rgba="0 .5 0 1" mass="1"/>
            <body name="left_leg2" pos="0.1216371928548099 0.21446310286663534 0.2593516826837463">
                <joint name="left_leg2_joint" type="hinge" axis="0 1 0" pos="0 0 0"/>
                <geom type="box" size="0.3749656120169089 0.07931403183633061 0.021520963779928473" rgba="0 .6 0 1" mass="1"/>
            </body>
        </body>
        <body name="right_leg1" pos="-0.28868093930315175 -0.15728901900239492 0.02306321997978858">
            <joint name="right_leg1_joint" type="hinge" axis="0 1 0" pos="0 0 0"/>
            <geom type="box" size="0.5 0.02 0.02" rgba="0 .5 0 1" mass="1"/>
            <body name="right_leg2" pos="0.6251074021799156 -0.16999999999999998 0.0918994138855487">
                <joint name="right_leg2_joint" type="hinge" axis="0 1 0" pos="0 0 0"/>
                <geom type="box" size="0.3395979229094689 0.15 0.1387702409856781" rgba="0 .6 0 1" mass="1"/>
            </body>
        </body>
    </body>
    </worldbody>
    <sensor>
        <framepos objtype="site" objname="marker"/>
        <velocimeter name="robot_velocity" site="robot_center"/>
    </sensor>
    <actuator>
        <position joint="left_leg1_joint" kp="10"/>
        <position joint="left_leg2_joint" kp="10"/>
        <position joint="right_leg1_joint" kp="10"/>
        <position joint="right_leg2_joint" kp="10"/>
    </actuator>
</mujoco>