<mujoco>
    <worldbody>
    <light diffuse=".5 .5 .5" pos="0 0 3" dir="0 0 -1"/>
    <geom type="plane" size="5 5 0.1" rgba=".9 0.9 0.9 1"/>
    <body name="main body" pos="0 0 .2">
        <joint type="free"/>
        <geom type="box" size="0.18622804523356223 0.15953373436601853 0.08920945230724807" rgba="0 0 1 1" mass="1"/>
        <site name="marker" pos="0 0 0" size="0.05"/>
        <site name="robot_center" pos="0 0 0" size="0.01"/>
        <body name="left_leg1" pos="-0.48 0.19503384737804105 -0.1">
            <joint name="left_leg1_joint" type="hinge" axis="0 1 0" pos="0 0 0"/>
            <geom type="box" size="0.5 0.03550011301202253 0.15" rgba="0 .5 0 1" mass="2"/>
            <body name="left_leg2" pos="0.6824694458343572 0.18550011301202252 -0.04">
                <joint name="left_leg2_joint" type="hinge" axis="0 1 0" pos="0 0 0"/>
                <geom type="box" size="0.5 0.15 0.15" rgba="0 .6 0 1" mass="2"/>
            </body>
        </body>
        <body name="right_leg1" pos="-0.48 -0.17953373436601852 -0.06353146835598492">
            <joint name="right_leg1_joint" type="hinge" axis="0 1 0" pos="0 0 0"/>
            <geom type="box" size="0.3 0.02 0.15" rgba="0 .5 0 1" mass="2"/>
            <body name="right_leg2" pos="0.17886077896008676 -0.153672721836102 -0.04">
                <joint name="right_leg2_joint" type="hinge" axis="0 1 0" pos="0 0 0"/>
                <geom type="box" size="0.39319472867698646 0.13367272183610202 0.02" rgba="0 .6 0 1" mass="2"/>
            </body>
        </body>
    </body>
    </worldbody>
    <sensor>
        <framepos objtype="site" objname="marker"/>
        <velocimeter name="robot_velocity" site="robot_center"/>
    </sensor>
    <actuator>
        <position joint="left_leg1_joint" kp="10"/>
        <position joint="left_leg2_joint" kp="10"/>
        <position joint="right_leg1_joint" kp="10"/>
        <position joint="right_leg2_joint" kp="10"/>
    </actuator>
</mujoco>